<?xml version="1.0" ?>
<robot name="ros" xmlns:xacro="http://www.ros.org/wiki/xacro">

<!-- <xacro:include filename="$(find bot)/description/robot.trans" /> -->

<material name="red">
  <color rgba="1.0 0.0 0.0 1.0"/>
</material>

<material name="yellow">
  <color rgba="1.0 1.0 0.0 1.0"/>
</material>

<material name="black">
  <color rgba="0.0 0.0 0.0 1.0"/>
</material>

<material name="white">
  <color rgba="1.0 1.0 1.0 1.0"/>
</material>

<!-- base link -->
<link name="base_link">
</link>

<!-- footprint -->
<joint name="base_footprint_joint" type="fixed">
  <parent link="base_link"/>
  <child link="base_footprint"/>
  <origin xyz="0 0 0" rpy="0 0 0"/>
</joint>

<link name="base_footprint">
</link>

<!-- chassis -->
<link name="chassis">
  <inertial>
    <origin xyz="0.0008189155791673744 -3.6256422630217844e-07 0.0441754200913135" rpy="0 0 0"/>
    <mass value="1"/>
    <inertia ixx="0.018351" iyy="0.018978" izz="0.030658" ixy="0.0" iyz="-0.0" ixz="4e-05"/>
  </inertial>
  <visual>
    <origin xyz="0 0 0" rpy="0 0 0"/>
    <geometry>
      <mesh filename="file://$(find hexa)/meshes/chassis.stl" scale="0.001 0.001 0.001"/>
    </geometry>
    <material name="yellow"/>
  </visual>
  <collision>
    <origin xyz="0 0 0" rpy="0 0 0"/>
    <geometry>
      <mesh filename="file://$(find hexa)/meshes/chassis.stl" scale="0.001 0.001 0.001"/>
    </geometry>
  </collision>
</link>

<joint name="chassis_joint" type="fixed">
  <origin xyz="-0.0 0.0 0.0" rpy="0 0 0"/>
  <parent link="base_link"/>
  <child link="chassis"/>
</joint>

<gazebo reference="chassis">
  <material>Gazebo/Yellow</material>
  <mu1>0.08</mu1>
  <mu2>0.08</mu2>
  <!-- <self_collide>true</self_collide>
  <gravity>true</gravity> -->
</gazebo>

<!-- left rare wheel -->
<link name="L_wheel">
  <inertial>
    <origin xyz="5.01953530179549e-14 -0.013499999999999956 0.0" rpy="0 0 0"/>
    <mass value="0.2"/>
    <inertia ixx="0.000227" iyy="0.000371" izz="0.000227" ixy="-0.0" iyz="-0.0" ixz="-0.0"/>
  </inertial>
  <visual>
    <origin xyz="-0.0 -0.095 -0.0325" rpy="0 0 0"/>
    <geometry>
      <mesh filename="file://$(find hexa)/meshes/L_wheel.stl" scale="0.001 0.001 0.001"/>
    </geometry>
    <material name="white"/>
  </visual>
  <collision>
    <origin xyz="-0.0 -0.095 -0.0325" rpy="0 0 0"/>
    <geometry>
      <mesh filename="file://$(find hexa)/meshes/L_wheel.stl" scale="0.001 0.001 0.001"/>
    </geometry>
  </collision>
</link>

<joint name="L_joint" type="continuous">
  <origin xyz="0.0 0.095 0.0325" rpy="0 0 0"/>
  <parent link="chassis"/>
  <child link="L_wheel"/>
  <axis xyz="0.0 1.0 0.0"/>
</joint>
<gazebo reference="L_wheel">
  <material>Gazebo/White</material>
  <!-- <mu1>0.2</mu1>
  <mu2>0.2</mu2> -->
  <!-- <self_collide>true</self_collide> -->
</gazebo>

<!-- right rare wheel -->
<link name="R_wheel">
  <inertial>
    <origin xyz="-2.5081206055828184e-14 0.013499999999999984 6.938893903907228e-18" rpy="0 0 0"/>
    <mass value="0.2"/>
    <inertia ixx="0.000227" iyy="0.000371" izz="0.000227" ixy="-0.0" iyz="0.0" ixz="0.0"/>
  </inertial>
  <visual>
    <origin xyz="-0.0 0.095 -0.0325" rpy="0 0 0"/>
    <geometry>
      <mesh filename="file://$(find hexa)/meshes/R_wheel.stl" scale="0.001 0.001 0.001"/>
    </geometry>
    <material name="white"/>
  </visual>
  <collision>
    <origin xyz="-0.0 0.095 -0.0325" rpy="0 0 0"/>
    <geometry>
      <mesh filename="file://$(find hexa)/meshes/R_wheel.stl" scale="0.001 0.001 0.001"/>
    </geometry>
  </collision>
</link>

<joint name="R_joint" type="continuous">
  <origin xyz="0.0 -0.095 0.0325" rpy="0 0 0"/>
  <parent link="chassis"/>
  <child link="R_wheel"/>
  <axis xyz="0.0 1.0 0.0"/>
</joint>

<gazebo reference="R_wheel">
  <material>Gazebo/White</material>
  <!-- <mu1>0.2</mu1>
  <mu2>0.2</mu2> -->
  <!-- <self_collide>true</self_collide> -->
</gazebo>

</robot>
